Workbook
Name Slicer_customer_segment: #N/A
Name Slicer_device_tier: #N/A
Name Slicer_governorate: #N/A
Name Slicer_operator: #N/A

Sheet egypt_telecom_calibrated_5000
A1: governorate | B1: Sum of satisfaction_score | C1: Count of customer_id | D1: Sum of complaints_count
A2: أسوان | B2: 221 | C2: 60 | D2: 46
A3: أسيوط | B3: 505 | C3: 138 | D3: 95
A4: الإسكندرية | B4: 1762 | C4: 490 | D4: 411
A5: الإسماعيلية | B5: 401 | C5: 110 | D5: 99 | I5: operator | J5: Sum of satisfaction_score | K5: Count of customer_id | L5: Sum of complaints_count | M5: Sum of monthly_revenue_EGP
A6: الأقصر | B6: 222 | C6: 61 | D6: 41 | I6: e& | J6: 3128 | K6: 870 | L6: 700 | M6: 140689.03
A7: البحر الأحمر | B7: 163 | C7: 46 | D7: 32 | I7: Orange | J7: 5107 | K7: 1395 | L7: 1194 | M7: 273765.67
A8: البحيرة | B8: 893 | C8: 246 | D8: 245 | I8: Vodafone | J8: 7578 | K8: 2120 | L8: 1926 | M8: 427367.76
A9: الجيزة | B9: 1844 | C9: 515 | D9: 501 | I9: WE | J9: 2223 | K9: 615 | L9: 550 | M9: 100453.27 | T9: plan_type | U9: Count of customer_id | V9: Average of data_used_GB | W9: Sum of monthly_revenue_EGP | AB9: plan_type | AC9: network_type | AD9: Sum of data_used_GB | AE9: Count of customer_id | AF9: Sum of satisfaction_score
A10: الدقهلية | B10: 1006 | C10: 278 | D10: 204 | I10: Grand Total | J10: 18036 | K10: 5000 | L10: 4370 | M10: 942275.73 | T10: Postpaid | U10: 836 | V10: 17.393947 | W10: 324233 | AB10: Postpaid | AD10: 14541.34 | AE10: 836 | AF10: 3000
A11: السويس | B11: 340 | C11: 99 | D11: 90 | T11: Prepaid | U11: 4164 | V11: 7.6986263 | W11: 618042.73 | AC11: 2G | AD11: 11.48 | AE11: 55 | AF11: 205
A12: الشرقية | B12: 1200 | C12: 329 | D12: 298 | T12: Grand Total | U12: 5000 | V12: 9.319684 | W12: 942275.73 | AC12: 3G | AD12: 4251.9 | AE12: 220 | AF12: 800
A13: الغربية | B13: 907 | C13: 248 | D13: 201 | AC13: 4G | AD13: 9505.7 | AE13: 518 | AF13: 1847
A14: الفيوم | B14: 400 | C14: 110 | D14: 93 | AC14: 5G | AD14: 772.26 | AE14: 43 | AF14: 148
A15: القاهرة | B15: 3361 | C15: 933 | D15: 839 | AB15: Prepaid | AD15: 32057.08 | AE15: 4164 | AF15: 15036
A16: القليوبية | B16: 1015 | C16: 283 | D16: 243 | V16: recharge_frequency | W16: (All) | AC16: 2G | AD16: 67.33 | AE16: 268 | AF16: 965
A17: المنوفية | B17: 730 | C17: 205 | D17: 147 | AC17: 3G | AD17: 9283.21 | AE17: 1130 | AF17: 4139
A18: المنيا | B18: 514 | C18: 142 | D18: 126 | V18: customer_segment | W18: Count of customer_id | X18: Average of satisfaction_score | Y18: Average of complaints_count | AC18: 4G | AD18: 21143.75 | AE18: 2584 | AF18: 9291
A19: الوادي الجديد | B19: 86 | C19: 22 | D19: 24 | K19: sum of monthly revenue | L19: gender | V19: Business | W19: 533 | X19: 3.6153846 | Y19: 0.84427767 | AC19: 5G | AD19: 1562.79 | AE19: 182 | AF19: 641
A20: بني سويف | B20: 363 | C20: 99 | D20: 101 | K20: age_group | L20: Female | M20: Male | N20: Grand Total | V20: Low | W20: 1262 | X20: 3.6180666 | Y20: 0.85736926 | AB20: Grand Total | AD20: 46598.42 | AE20: 5000 | AF20: 18036
A21: بورسعيد | B21: 294 | C21: 82 | D21: 74 | K21: 18-25 | L21: 95991.34 | M21: 128542.55 | N21: 224533.89 | V21: Regular | W21: 2946 | X21: 3.5960625 | Y21: 0.88289206
A22: جنوب سيناء | B22: 79 | C22: 24 | D22: 18 | K22: 26-35 | L22: 125005.24 | M22: 154914.5 | N22: 279919.74 | V22: VIP | W22: 259 | X22: 3.6640927 | Y22: 0.91505792
A23: دمياط | B23: 214 | C23: 57 | D23: 47 | K23: 36-45 | L23: 82702.97 | M23: 112976.9 | N23: 195679.87 | V23: Grand Total | W23: 5000 | X23: 3.6072 | Y23: 0.874
A24: سوهاج | B24: 533 | C24: 145 | D24: 156 | K24: 46-55 | L24: 53469.72 | M24: 76789.43 | N24: 130259.15
A25: شمال سيناء | B25: 87 | C25: 26 | D25: 20 | K25: 55+ | L25: 45010.89 | M25: 66872.19 | N25: 111883.08
A26: قنا | B26: 394 | C26: 108 | D26: 79 | K26: Grand Total | L26: 402180.16 | M26: 540095.57 | N26: 942275.73
A27: كفر الشيخ | B27: 442 | C27: 127 | D27: 128
A28: مطروح | B28: 60 | C28: 17 | D28: 12 | W28: Churn Rate | Y28: Avg. Satisfaction | AA28: Total customer | AD28: customer_segment | AE28: Values
A29: Grand Total | B29: 18036 | C29: 5000 | D29: 4370 | W29: ='egypt_telecom_dataset-1'!E29/'egypt_telecom_dataset-1'!C29 -> 0.029454545 | Y29: =egypt_telecom_calibrated_5000!B29/egypt_telecom_calibrated_5000!C29 -> 3.6072 | AA29: =egypt_telecom_calibrated_5000!C29 -> 5000 | AD29: Business | AF29: Low | AH29: Regular | AJ29: VIP | AL29: Total Sum of monthly_revenue_EGP | AM29: Total Average of data_used_GB
X30: Total Complaints | Z30: total revenue | AC30: has_ewallet | AD30: Sum of monthly_revenue_EGP | AE30: Average of data_used_GB | AF30: Sum of monthly_revenue_EGP | AG30: Average of data_used_GB | AH30: Sum of monthly_revenue_EGP | AI30: Average of data_used_GB | AJ30: Sum of monthly_revenue_EGP | AK30: Average of data_used_GB
X31: =egypt_telecom_calibrated_5000!D29 -> 4370 | Z31: =egypt_telecom_calibrated_5000!M10 -> 942275.73 | AC31: 0 | AD31: 111368.14 | AE31: 18.958764 | AF31: 63380.18 | AG31: 2.7670291 | AH31: 317741.52 | AI31: 8.9696148 | AJ31: 95659.72 | AK31: 24.095118 | AL31: 588149.56 | AM31: 9.3258302
AC32: 1 | AD32: 63777.47 | AE32: 17.532703 | AF32: 44010.75 | AG32: 2.6974522 | AH32: 187578.39 | AI32: 9.1628639 | AJ32: 58759.56 | AK32: 28.924045 | AL32: 354126.17 | AM32: 9.3087194
M33: device_tier | N33: Sum of monthly_revenue_EGP | O33: Sum of data_used_GB | AC33: Grand Total | AD33: 175145.61 | AE33: 18.46379 | AF33: 107390.93 | AG33: 2.7410618 | AH33: 505319.91 | AI33: 9.0385574 | AJ33: 154419.28 | AK33: 25.754479 | AL33: 942275.73 | AM33: 9.319684
M34: Basic Smartphone | N34: 13493.46 | O34: 24.84
M35: Budget Smartphone | N35: 247396.16 | O35: 13237.17
M36: Feature Phone | N36: 88428.72 | O36: 3392.6
M37: Mid Smartphone | N37: 373784.81 | O37: 19213.32
M38: Premium Smartphone | N38: 200514.42 | O38: 9801.31
M39: Tablet | N39: 18658.16 | O39: 929.18
M40: Grand Total | N40: 942275.73 | O40: 46598.42

Sheet Sheet 5
E2: =_xlfn.UNICHAR(128101) -> 👥 | F2: Total customer | I2: =_xlfn.UNICHAR(128176) -> 💰 | J2: Total revenue | M2: =_xlfn.UNICHAR(11088) -> ⭐ | N2: Avg. Satisfaction | Q2: =_xlfn.UNICHAR(128222) -> 📞 | R2: Total Complaints | U2: =_xlfn.UNICHAR(128201) -> 📉 | V2: Churn Rate
F4: =egypt_telecom_calibrated_5000!C29 -> 5000 | J4: =egypt_telecom_calibrated_5000!M10 -> 942275.73 | N4: =egypt_telecom_calibrated_5000!B29/egypt_telecom_calibrated_5000!C29 -> 3.6072 | R4: =egypt_telecom_calibrated_5000!D29 -> 4370 | V4: ='egypt_telecom_dataset-1'!E29/'egypt_telecom_dataset-1'!C29 -> 0.029454545
F47: Worst 5 Governorates by Latency

Sheet Sheet4
E2: =_xlfn.UNICHAR(128101) -> 👥 | F2: Total customer | I2: =_xlfn.UNICHAR(128176) -> 💰 | J2: Total revenue | M2: =_xlfn.UNICHAR(11088) -> ⭐ | N2: Avg. Satisfaction | Q2: =_xlfn.UNICHAR(128222) -> 📞 | R2: Total Complaints | U2: =_xlfn.UNICHAR(128201) -> 📉 | V2: Churn Rate
F4: =egypt_telecom_calibrated_5000!C29 -> 5000 | J4: =egypt_telecom_calibrated_5000!M10 -> 942275.73 | N4: =egypt_telecom_calibrated_5000!B29/egypt_telecom_calibrated_5000!C29 -> 3.6072 | R4: =egypt_telecom_calibrated_5000!D29 -> 4370 | V4: ='egypt_telecom_dataset-1'!E29/'egypt_telecom_dataset-1'!C29 -> 0.029454545

Sheet Sheet2
A3: governorate | B3: Sum of Sum of satisfaction_score
A4: الإسكندرية | B4: 1898
A5: الجيزة | B5: 2148
A6: الدقهلية | B6: 1246
A7: الشرقية | B7: 1363
A8: القاهرة | B8: 3595
A9: Grand Total | B9: 10250

Sheet egypt_telecom_dataset-1
A1: governorate | B1: Sum of satisfaction_score | C1: Count of customer_id | D1: Sum of complaints_count | E1: Sum of churn | F1: Sum of monthly_revenue_EGP
A2: شمال سيناء | B2: 57 | C2: 16 | D2: 11 | E2: 0 | F2: 1795.85
A3: جنوب سيناء | B3: 63 | C3: 20 | D3: 19 | E3: 1 | F3: 2570.71
A4: مطروح | B4: 79 | C4: 22 | D4: 21 | E4: 0 | F4: 1832.01
A5: الوادي الجديد | B5: 85 | C5: 24 | D5: 32 | E5: 0 | F5: 3353.25
A6: البحر الأحمر | B6: 175 | C6: 50 | D6: 44 | E6: 0 | F6: 5991.19
A7: الأقصر | B7: 193 | C7: 50 | D7: 50 | E7: 1 | F7: 6890.21
A8: أسوان | B8: 216 | C8: 58 | D8: 44 | E8: 0 | F8: 7113.62
A9: دمياط | B9: 236 | C9: 64 | D9: 62 | E9: 3 | F9: 12251.02
A10: قنا | B10: 384 | C10: 108 | D10: 84 | E10: 5 | F10: 14241.88
A11: السويس | B11: 393 | C11: 105 | D11: 75 | E11: 4 | F11: 14477.08
A12: بورسعيد | B12: 395 | C12: 107 | D12: 83 | E12: 3 | F12: 16913.99
A13: الإسماعيلية | B13: 422 | C13: 118 | D13: 115 | E13: 5 | F13: 21420.21
A14: الفيوم | B14: 431 | C14: 117 | D14: 105 | E14: 3 | F14: 15519.62
A15: بني سويف | B15: 452 | C15: 121 | D15: 132 | E15: 3 | F15: 17472.71 | T15: governorate | U15: Sum of monthly_revenue_EGP | Y15: governorate | Z15: Sum of satisfaction_score | AD15: governorate | AE15: Sum of complaints_count | AF15: Sum of churn
A16: أسيوط | B16: 544 | C16: 152 | D16: 123 | E16: 6 | F16: 19672.38 | T16: شمال سيناء | U16: 1795.85 | Y16: القاهرة | Z16: 3595 | AD16: شمال سيناء | AE16: 11 | AF16: 0
A17: المنيا | B17: 555 | C17: 155 | D17: 123 | E17: 5 | F17: 21634.05 | T17: جنوب سيناء | U17: 2570.71 | Y17: الجيزة | Z17: 2148 | AD17: جنوب سيناء | AE17: 19 | AF17: 1
A18: سوهاج | B18: 582 | C18: 165 | D18: 142 | E18: 3 | F18: 25916.56 | T18: مطروح | U18: 1832.01 | Y18: الإسكندرية | Z18: 1898 | AD18: مطروح | AE18: 21 | AF18: 0
A19: كفر الشيخ | B19: 584 | C19: 160 | D19: 158 | E19: 5 | F19: 22129.05 | T19: الوادي الجديد | U19: 3353.25 | Y19: الشرقية | Z19: 1363 | AD19: الوادي الجديد | AE19: 32 | AF19: 0
A20: المنوفية | B20: 803 | C20: 224 | D20: 200 | E20: 7 | F20: 27690.5 | T20: البحر الأحمر | U20: 5991.19 | Y20: الدقهلية | Z20: 1246 | AD20: البحر الأحمر | AE20: 44 | AF20: 0
A21: البحيرة | B21: 890 | C21: 248 | D21: 211 | E21: 9 | F21: 29119.35 | T21: الأقصر | U21: 6890.21 | Y21: القليوبية | Z21: 1171 | AD21: الأقصر | AE21: 50 | AF21: 1
A22: الغربية | B22: 899 | C22: 250 | D22: 234 | E22: 7 | F22: 38924.34 | T22: أسوان | U22: 7113.62 | Y22: الغربية | Z22: 899 | AD22: أسوان | AE22: 44 | AF22: 0
A23: القليوبية | B23: 1171 | C23: 325 | D23: 304 | E23: 8 | F23: 46820.95 | T23: دمياط | U23: 12251.02 | Y23: البحيرة | Z23: 890 | AD23: دمياط | AE23: 62 | AF23: 3
A24: الدقهلية | B24: 1246 | C24: 348 | D24: 342 | E24: 13 | F24: 51321.79 | T24: قنا | U24: 14241.88 | Y24: المنوفية | Z24: 803 | AD24: قنا | AE24: 84 | AF24: 5
A25: الشرقية | B25: 1363 | C25: 369 | D25: 305 | E25: 17 | F25: 51738.89 | T25: السويس | U25: 14477.08 | Y25: كفر الشيخ | Z25: 584 | AD25: السويس | AE25: 75 | AF25: 4
A26: الإسكندرية | B26: 1898 | C26: 527 | D26: 469 | E26: 9 | F26: 77699.94 | T26: بورسعيد | U26: 16913.99 | Y26: سوهاج | Z26: 582 | AD26: بورسعيد | AE26: 83 | AF26: 3
A27: الجيزة | B27: 2148 | C27: 591 | D27: 501 | E27: 15 | F27: 87302.7 | T27: الإسماعيلية | U27: 21420.21 | Y27: المنيا | Z27: 555 | AD27: الإسماعيلية | AE27: 115 | AF27: 5
... A29: Grand Total | B29: 19859 | C29: 5500 | D29: 4853 | E29: 162 | F29: 794667.76 | T29: بني سويف | U29: 17472.71 | Y29: بني سويف | Z29: 452 | AD29: بني سويف | AE29: 132 | AF29: 3
T30: أسيوط | U30: 19672.38 | Y30: الفيوم | Z30: 431 | AD30: أسيوط | AE30: 123 | AF30: 6
T31: المنيا | U31: 21634.05 | Y31: الإسماعيلية | Z31: 422 | AD31: المنيا | AE31: 123 | AF31: 5
T32: سوهاج | U32: 25916.56 | Y32: بورسعيد | Z32: 395 | AD32: سوهاج | AE32: 142 | AF32: 3
T33: كفر الشيخ | U33: 22129.05 | Y33: السويس | Z33: 393 | AD33: كفر الشيخ | AE33: 158 | AF33: 5
T34: المنوفية | U34: 27690.5 | Y34: قنا | Z34: 384 | AD34: المنوفية | AE34: 200 | AF34: 7
T35: البحيرة | U35: 29119.35 | Y35: دمياط | Z35: 236 | AD35: البحيرة | AE35: 211 | AF35: 9
T36: الغربية | U36: 38924.34 | Y36: أسوان | Z36: 216 | AD36: الغربية | AE36: 234 | AF36: 7
T37: القليوبية | U37: 46820.95 | Y37: الأقصر | Z37: 193 | AD37: القليوبية | AE37: 304 | AF37: 8
T38: الدقهلية | U38: 51321.79 | Y38: البحر الأحمر | Z38: 175 | AD38: الدقهلية | AE38: 342 | AF38: 13
T39: الشرقية | U39: 51738.89 | Y39: الوادي الجديد | Z39: 85 | AD39: الشرقية | AE39: 305 | AF39: 17
T40: الإسكندرية | U40: 77699.94 | Y40: مطروح | Z40: 79 | AD40: الإسكندرية | AE40: 469 | AF40: 9
T41: الجيزة | U41: 87302.7 | Y41: جنوب سيناء | Z41: 63 | AD41: الجيزة | AE41: 501 | AF41: 15
...

Sheet tiles_raw
A1: Ookla-Format Synthetic Dataset — Egypt Mobile Network Performance (Q4 2024)
A2: avg_d_kbps | B2: avg_u_kbps | C2: avg_lat_ms | D2: tests | E2: devices | F2: governorate_en | G2: governorate_ar | H2: tile_lat | I2: tile_lon | J2: quadkey
A3: 29915 | B3: 7942 | C3: 52.5 | D3: 792 | E3: 520 | F3: Alexandria | G3: الإسكندرية | H3: 31.425432 | I3: 29.685793 | J3: 1221210102231100
A4: 35335 | B4: 9960 | C4: 53.6 | D4: 957 | E4: 456 | F4: Alexandria | G4: الإسكندرية | H4: 31.434097 | I4: 29.710815 | J4: 1221210102302220
A5: 26365 | B5: 8798 | C5: 48 | D5: 2705 | E5: 1731 | F5: Alexandria | G5: الإسكندرية | H5: 31.441989 | I5: 29.839725 | J5: 1221210102313202
A6: 29185 | B6: 12412 | C6: 53 | D6: 1899 | E6: 888 | F6: Alexandria | G6: الإسكندرية | H6: 31.443331 | I6: 29.88086 | J6: 1221210102313311
A7: 29525 | B7: 8599 | C7: 40.3 | D7: 3020 | E7: 1763 | F7: Alexandria | G7: الإسكندرية | H7: 31.39705 | I7: 29.710057 | J7: 1221210102320220
A8: 27462 | B8: 6934 | C8: 40.9 | D8: 2680 | E8: 1510 | F8: Alexandria | G8: الإسكندرية | H8: 31.384312 | I8: 29.793552 | J8: 1221210102323113 | AA8: governorate_en | AB8: Average of avg_d_kbps | AC8: Sum of avg_lat_ms | AD8: Sum of avg_u_kbps
A9: 26180 | B9: 14657 | C9: 40.4 | D9: 1683 | E9: 962 | F9: Alexandria | G9: الإسكندرية | H9: 31.372392 | I9: 29.779607 | J9: 1221210102323301 | AA9: North Sinai | AB9: 8845 | AC9: 1069 | AD9: 47909
A10: 32843 | B10: 8229 | C10: 32.6 | D10: 849 | E10: 384 | F10: Alexandria | G10: الإسكندرية | H10: 31.421808 | I10: 29.940648 | J10: 1221210103221012 | AA10: New Valley | AB10: 9009.25 | AC10: 1146.3 | AD10: 47573
A11: 31123 | B11: 12252 | C11: 42.7 | D11: 3103 | E11: 2140 | F11: Alexandria | G11: الإسكندرية | H11: 31.382179 | I11: 29.933201 | J11: 1221210103223003 | AA11: South Sinai | AB11: 9921.75 | AC11: 996.3 | AD11: 53077
A12: 27814 | B12: 12794 | C12: 48.8 | D12: 1176 | E12: 746 | F12: Alexandria | G12: الإسكندرية | H12: 31.380061 | I12: 29.959338 | J12: 1221210103223121 | AA12: Matrouh | AB12: 10850.333 | AC12: 1096.3 | AD12: 49240
A13: 23874 | B13: 10784 | C13: 49.1 | D13: 811 | E13: 441 | F13: Alexandria | G13: الإسكندرية | H13: 31.410424 | I13: 29.999354 | J13: 1221210103230123 | AA13: Red Sea | AB13: 11070.667 | AC13: 1064.2 | AD13: 46503
A14: 15394 | B14: 13029 | C14: 38.1 | D14: 3234 | E14: 2135 | F14: Alexandria | G14: الإسكندرية | H14: 31.240986 | I14: 29.685326 | J14: 1221210120031322 | AA14: Kafr El-Sheikh | AB14: 19075.514 | AC14: 2268 | AD14: 268357
A15: 30175 | B15: 12890 | C15: 42.1 | D15: 1768 | E15: 1168 | F15: Alexandria | G15: الإسكندرية | H15: 31.338298 | I15: 29.749772 | J15: 1221210120100133 | AA15: Gharbia | AB15: 19120.914 | AC15: 2128.7 | AD15: 253357
A16: 31419 | B16: 8435 | C16: 52.6 | D16: 2228 | E16: 1048 | F16: Alexandria | G16: الإسكندرية | H16: 31.350293 | I16: 29.793616 | J16: 1221210120101111 | AA16: Ismailia | AB16: 19403.6 | AC16: 2306.3 | AD16: 262714
A17: 21462 | B17: 10999 | C17: 41 | D17: 1119 | E17: 709 | F17: Alexandria | G17: الإسكندرية | H17: 31.301232 | I17: 29.775331 | J17: 1221210120103122 | AA17: Suez | AB17: 19633.371 | AC17: 2054.9 | AD17: 259083
A18: 34030 | B18: 9449 | C18: 39.5 | D18: 2295 | E18: 1477 | F18: Alexandria | G18: الإسكندرية | H18: 31.208856 | I18: 29.735784 | J18: 1221210120122321 | AA18: Monufia | AB18: 19826.171 | AC18: 2295.3 | AD18: 275969
A19: 26038 | B19: 11359 | C19: 41.8 | D19: 2323 | E19: 1233 | F19: Alexandria | G19: الإسكندرية | H19: 31.26311 | I19: 29.838448 | J19: 1221210120130133 | AA19: Fayyum | AB19: 19838.057 | AC19: 2056 | AD19: 251454
A20: 26431 | B20: 8530 | C20: 54 | D20: 2922 | E20: 1771 | F20: Alexandria | G20: الإسكندرية | H20: 31.268215 | I20: 29.849617 | J20: 1221210120131021 | AA20: Aswan | AB20: 19869.057 | AC20: 2222.5 | AD20: 248598
... A36: 28055 | B36: 8031 | C36: 67.5 | D36: 1109 | E36: 717 | F36: Alexandria | G36: الإسكندرية | H36: 31.292783 | I36: 30.157397 | J36: 1221210121112201 | AA36: Grand Total | AB36: 21502.597 | AC36: 57875.9 | AD36: 7641575
A37: 34646 | B37: 6894 | C37: 62.6 | D37: 2721 | E37: 1551 | F37: Alexandria | G37: الإسكندرية | H37: 31.269263 | I37: 30.105485 | J37: 1221210121121002
A38: 32010 | B38: 10802 | C38: 39.1 | D38: 3030 | E38: 2088 | F38: Alexandria | G38: الإسكندرية | H38: 31.259078 | I38: 30.126182 | J38: 1221210121121300
A39: 22397 | B39: 8343 | C39: 48 | D39: 843 | E39: 435 | F39: Alexandria | G39: الإسكندرية | H39: 31.23377 | I39: 30.097193 | J39: 1221210121122113
A40: 27016 | B40: 10444 | C40: 33.9 | D40: 2670 | E40: 1245 | F40: Alexandria | G40: الإسكندرية | H40: 31.25001 | I40: 30.163825 | J40: 1221210121130231
A41: 29845 | B41: 10127 | C41: 50.3 | D41: 1842 | E41: 848 | F41: Alexandria | G41: الإسكندرية | H41: 31.190253 | I41: 29.913334 | J41: 1221210121200121
A42: 21540 | B42: 9432 | C42: 37.3 | D42: 1602 | E42: 725 | F42: Alexandria | G42: الإسكندرية | H42: 31.199444 | I42: 29.966175 | J42: 1221210121201111
A43: 27198 | B43: 6175 | C43: 49 | D43: 973 | E43: 544 | F43: Alexandria | G43: الإسكندرية | H43: 31.195797 | I43: 30.010114 | J43: 1221210121210113
A44: 26860 | B44: 9932 | C44: 36.3 | D44: 2401 | E44: 1551 | F44: Alexandria | G44: الإسكندرية | H44: 31.190761 | I44: 30.029601 | J44: 1221210121211030
A45: 33082 | B45: 9091 | C45: 31.8 | D45: 1541 | E45: 881 | F45: Alexandria | G45: الإسكندرية | H45: 31.186605 | I45: 30.035795 | J45: 1221210121211033
A46: 22369 | B46: 9731 | C46: 63.8 | D46: 3112 | E46: 1896 | F46: Alexandria | G46: الإسكندرية | H46: 31.17761 | I46: 30.033585 | J46: 1221210121211213
A47: 28836 | B47: 11941 | C47: 45.4 | D47: 2604 | E47: 1377 | F47: Alexandria | G47: الإسكندرية | H47: 31.165153 | I47: 29.995163 | J47: 1221210121212100
A48: 22969 | B48: 10118 | C48: 51 | D48: 1853 | E48: 1205 | F48: Alexandria | G48: الإسكندرية | H48: 31.134263 | I48: 29.991789 | J48: 1221210121212231
... A967: 16205 | B967: 6352 | C967: 72.5 | D967: 1161 | E967: 760 | F967: Suez | G967: السويس | H967: 29.795259 | I967: 32.659352 | J967: 1221211322113003

Sheet Sheet5
A3: governorate_en | B3: Sum of Sum of avg_d_mbps
A4: Alexandria | B4: 28.6
A5: Beni Suef | B5: 21.8
A6: Cairo | B6: 28.2
A7: Giza | B7: 27.9
A8: Minya | B8: 20.9
A9: Grand Total | B9: 127.4

Sheet gov_summary
CG9: governorate_en | CH9: Average of Sum of avg_lat_ms
CG10: South Sinai | CH10: 83
CG11: Red Sea | CH11: 88.7
AT12: governorate_en | AU12: Sum of avg_d_mbps | AZ12: governorate_en | BA12: Sum of avg_lat_ms | BG12: governorate_en | BH12: Sum of avg_d_kbps | BI12: Sum of avg_u_kbps | BN12: governorate_en | BO12: Sum of total_tests | BS12: governorate_en | BT12: Sum of Sum of avg_d_mbps | CG12: North Sinai | CH12: 89.1
AT13: Alexandria | AU13: 28.6 | AZ13: Alexandria | BA13: 48.1 | BG13: Alexandria | BH13: 28552 | BI13: 9913 | BN13: Alexandria | BO13: 155411 | BS13: Alexandria | BT13: 28.6 | CG13: New Valley | CH13: 95.5
W14: governorate_en | X14: Sum of avg_d_kbps | Y14: Sum of avg_u_kbps | Z14: Sum of avg_lat_ms | AA14: Sum of avg_d_mbps | AB14: Sum of total_tests | AC14: Sum of total_devices | AD14: Sum of tile_count | AT14: Aswan | AU14: 19.9 | AZ14: Aswan | BA14: 63.5 | BG14: Aswan | BH14: 19869 | BI14: 7103 | BN14: Aswan | BO14: 35161 | BS14: Beni Suef | BT14: 21.8 | CG14: Matrouh | CH14: 91.4
L15: governorate_en | M15: Sum of avg_lat_ms | N15: Sum of avg_d_mbps | W15: Alexandria | X15: 28552 | Y15: 9913 | Z15: 48.1 | AA15: 28.6 | AB15: 155411 | AC15: 89901 | AD15: 80 | AT15: Asyut | AU15: 20.5 | AZ15: Asyut | BA15: 57.9 | BG15: Asyut | BH15: 20476 | BI15: 7375 | BN15: Asyut | BO15: 33796 | BS15: Cairo | BT15: 28.2 | CG15: Grand Total | CH15: 89.54
L16: Alexandria | M16: 48.1 | N16: 28.6 | W16: Aswan | X16: 19869 | Y16: 7103 | Z16: 63.5 | AA16: 19.9 | AB16: 35161 | AC16: 19155 | AD16: 35 | AT16: Beheira | AU16: 19.9 | AZ16: Beheira | BA16: 61.4 | BG16: Beheira | BH16: 19934 | BI16: 8067 | BN16: Beheira | BO16: 33297 | BS16: Giza | BT16: 27.9
L17: Aswan | M17: 63.5 | N17: 19.9 | W17: Asyut | X17: 20476 | Y17: 7375 | Z17: 57.9 | AA17: 20.5 | AB17: 33796 | AC17: 19146 | AD17: 35 | AT17: Beni Suef | AU17: 21.8 | AZ17: Beni Suef | BA17: 62.8 | BG17: Beni Suef | BH17: 21835 | BI17: 7442 | BN17: Beni Suef | BO17: 33770 | BS17: Minya | BT17: 20.9
L18: Asyut | M18: 57.9 | N18: 20.5 | W18: Beheira | X18: 19934 | Y18: 8067 | Z18: 61.4 | AA18: 19.9 | AB18: 33297 | AC18: 18598 | AD18: 35 | AT18: Cairo | AU18: 28.2 | AZ18: Cairo | BA18: 48.9 | BG18: Cairo | BH18: 28178 | BI18: 10076 | BN18: Cairo | BO18: 144487
L19: Beheira | M19: 61.4 | N19: 19.9 | W19: Beni Suef | X19: 21835 | Y19: 7442 | Z19: 62.8 | AA19: 21.8 | AB19: 33770 | AC19: 19693 | AD19: 35 | AT19: Dakahlia | AU19: 20.2 | AZ19: Dakahlia | BA19: 64.6 | BG19: Dakahlia | BH19: 20238 | BI19: 7771 | BN19: Dakahlia | BO19: 38916
L20: Beni Suef | M20: 62.8 | N20: 21.8 | W20: Cairo | X20: 28178 | Y20: 10076 | Z20: 48.9 | AA20: 28.2 | AB20: 144487 | AC20: 82117 | AD20: 80 | AT20: Damietta | AU20: 20.2 | AZ20: Damietta | BA20: 56.9 | BG20: Damietta | BH20: 20206 | BI20: 7629 | BN20: Damietta | BO20: 37619
L21: Cairo | M21: 48.9 | N21: 28.2 | W21: Dakahlia | X21: 20238 | Y21: 7771 | Z21: 64.6 | AA21: 20.2 | AB21: 38916 | AC21: 22381 | AD21: 35 | AI21: Avg. Upload Speed (Kbps) | AL21: Avg. Download Speed (Mbps) | AO21: Avg. Latency (ms) | AT21: Fayyum | AU21: 19.8 | AZ21: Fayyum | BA21: 58.7 | BG21: Fayyum | BH21: 19838 | BI21: 7184 | BN21: Fayyum | BO21: 33777
L22: Dakahlia | M22: 64.6 | N22: 20.2 | W22: Damietta | X22: 20206 | Y22: 7629 | Z22: 56.9 | AA22: 20.2 | AB22: 37619 | AC22: 21499 | AD22: 35 | AI22: =AVERAGE(gov_summary!Y15:Y41) -> 7160.1111 | AL22: =AVERAGE(gov_summary!AA15:AA41) -> 19.137037 | AO22: =AVERAGE(gov_summary!Z15:Z41) -> 65.181481 | AT22: Gharbia | AU22: 19.1 | AZ22: Gharbia | BA22: 60.8 | BG22: Gharbia | BH22: 19121 | BI22: 7239 | BN22: Gharbia | BO22: 32433
L23: Damietta | M23: 56.9 | N23: 20.2 | W23: Fayyum | X23: 19838 | Y23: 7184 | Z23: 58.7 | AA23: 19.8 | AB23: 33777 | AC23: 18937 | AD23: 35 | AT23: Giza | AU23: 27.9 | AZ23: Giza | BA23: 49.3 | BG23: Giza | BH23: 27866 | BI23: 9866 | BN23: Giza | BO23: 156970
L24: Fayyum | M24: 58.7 | N24: 19.8 | W24: Gharbia | X24: 19121 | Y24: 7239 | Z24: 60.8 | AA24: 19.1 | AB24: 32433 | AC24: 18000 | AD24: 35 | AJ24: Total Tests | AN24: Total Tiles | AT24: Ismailia | AU24: 19.4 | AZ24: Ismailia | BA24: 65.9 | BG24: Ismailia | BH24: 19404 | BI24: 7506 | BN24: Ismailia | BO24: 34708
L25: Gharbia | M25: 60.8 | N25: 19.1 | W25: Giza | X25: 27866 | Y25: 9866 | Z25: 49.3 | AA25: 27.9 | AB25: 156970 | AC25: 92319 | AD25: 80 | AJ25: =gov_summary!AB42 -> 1133831 | AN25: =gov_summary!AD42 -> 965 | AT25: Kafr El-Sheikh | AU25: 19.1 | AZ25: Kafr El-Sheikh | BA25: 64.8 | BG25: Kafr El-Sheikh | BH25: 19076 | BI25: 7667 | BN25: Kafr El-Sheikh | BO25: 37409
L26: Giza | M26: 49.3 | N26: 27.9 | W26: Ismailia | X26: 19404 | Y26: 7506 | Z26: 65.9 | AA26: 19.4 | AB26: 34708 | AC26: 18845 | AD26: 35 | AT26: Luxor | AU26: 19.9 | AZ26: Luxor | BA26: 60.9 | BG26: Luxor | BH26: 19878 | BI26: 7431 | BN26: Luxor | BO26: 34412
L27: Ismailia | M27: 65.9 | N27: 19.4 | W27: Kafr El-Sheikh | X27: 19076 | Y27: 7667 | Z27: 64.8 | AA27: 19.1 | AB27: 37409 | AC27: 21410 | AD27: 35 | AT27: Matrouh | AU27: 10.8 | AZ27: Matrouh | BA27: 91.4 | BG27: Matrouh | BH27: 10850 | BI27: 4103 | BN27: Matrouh | BO27: 2718
L28: Kafr El-Sheikh | M28: 64.8 | N28: 19.1 | W28: Luxor | X28: 19878 | Y28: 7431 | Z28: 60.9 | AA28: 19.9 | AB28: 34412 | AC28: 20330 | AD28: 35 | AT28: Minya | AU28: 20.9 | AZ28: Minya | BA28: 62.2 | BG28: Minya | BH28: 20873 | BI28: 7563 | BN28: Minya | BO28: 35380
L29: Luxor | M29: 60.9 | N29: 19.9 | W29: Matrouh | X29: 10850 | Y29: 4103 | Z29: 91.4 | AA29: 10.8 | AB29: 2718 | AC29: 1485 | AD29: 12 | AT29: Monufia | AU29: 19.8 | AZ29: Monufia | BA29: 65.6 | BG29: Monufia | BH29: 19826 | BI29: 7885 | BN29: Monufia | BO29: 35429
L30: Matrouh | M30: 91.4 | N30: 10.8 | W30: Minya | X30: 20873 | Y30: 7563 | Z30: 62.2 | AA30: 20.9 | AB30: 35380 | AC30: 19762 | AD30: 35 | AT30: New Valley | AU30: 9 | AZ30: New Valley | BA30: 95.5 | BG30: New Valley | BH30: 9009 | BI30: 3964 | BN30: New Valley | BO30: 2813
L31: Minya | M31: 62.2 | N31: 20.9 | W31: Monufia | X31: 19826 | Y31: 7885 | Z31: 65.6 | AA31: 19.8 | AB31: 35429 | AC31: 19752 | AD31: 35 | AT31: North Sinai | AU31: 8.8 | AZ31: North Sinai | BA31: 89.1 | BG31: North Sinai | BH31: 8845 | BI31: 3992 | BN31: North Sinai | BO31: 2200
L32: Monufia | M32: 65.6 | N32: 19.8 | W32: New Valley | X32: 9009 | Y32: 3964 | Z32: 95.5 | AA32: 9 | AB32: 2813 | AC32: 1664 | AD32: 12 | AT32: Port Said | AU32: 20.3 | AZ32: Port Said | BA32: 59.6 | BG32: Port Said | BH32: 20288 | BI32: 8051 | BN32: Port Said | BO32: 35584
L33: New Valley | M33: 95.5 | N33: 9 | W33: North Sinai | X33: 8845 | Y33: 3992 | Z33: 89.1 | AA33: 8.8 | AB33: 2200 | AC33: 1355 | AD33: 12 | AT33: Qalyubia | AU33: 20.6 | AZ33: Qalyubia | BA33: 59.4 | BG33: Qalyubia | BH33: 20554 | BI33: 7350 | BN33: Qalyubia | BO33: 31730
L34: North Sinai | M34: 89.1 | N34: 8.8 | W34: Port Said | X34: 20288 | Y34: 8051 | Z34: 59.6 | AA34: 20.3 | AB34: 35584 | AC34: 21427 | AD34: 35 | AT34: Qena | AU34: 20.5 | AZ34: Qena | BA34: 59.7 | BG34: Qena | BH34: 20518 | BI34: 7140 | BN34: Qena | BO34: 38055
L35: Port Said | M35: 59.6 | N35: 20.3 | W35: Qalyubia | X35: 20554 | Y35: 7350 | Z35: 59.4 | AA35: 20.6 | AB35: 31730 | AC35: 18385 | AD35: 35 | AT35: Red Sea | AU35: 11.1 | AZ35: Red Sea | BA35: 88.7 | BG35: Red Sea | BH35: 11071 | BI35: 3875 | BN35: Red Sea | BO35: 3073
L36: Qalyubia | M36: 59.4 | N36: 20.6 | W36: Qena | X36: 20518 | Y36: 7140 | Z36: 59.7 | AA36: 20.5 | AB36: 38055 | AC36: 21163 | AD36: 35 | AT36: Sharqia | AU36: 20.1 | AZ36: Sharqia | BA36: 59 | BG36: Sharqia | BH36: 20057 | BI36: 7946 | BN36: Sharqia | BO36: 34536
L37: Qena | M37: 59.7 | N37: 20.5 | W37: Red Sea | X37: 11071 | Y37: 3875 | Z37: 88.7 | AA37: 11.1 | AB37: 3073 | AC37: 1766 | AD37: 12 | AT37: Sohag | AU37: 20.8 | AZ37: Sohag | BA37: 63.5 | BG37: Sohag | BH37: 20830 | BI37: 7360 | BN37: Sohag | BO37: 36593
... L39: Sharqia | M39: 59 | N39: 20.1 | W39: Sohag | X39: 20830 | Y39: 7360 | Z39: 63.5 | AA39: 20.8 | AB39: 36593 | AC39: 21093 | AD39: 35 | AT39: Suez | AU39: 19.6 | AZ39: Suez | BA39: 58.7 | BG39: Suez | BH39: 19633 | BI39: 7402 | BN39: Suez | BO39: 30880
L40: Sohag | M40: 63.5 | N40: 20.8 | W40: South Sinai | X40: 9922 | Y40: 4423 | Z40: 83 | AA40: 9.9 | AB40: 2674 | AC40: 1605 | AD40: 12 | AT40: Grand Total | AU40: 516.7
L41: South Sinai | M41: 83 | N41: 9.9 | W41: Suez | X41: 19633 | Y41: 7402 | Z41: 58.7 | AA41: 19.6 | AB41: 30880 | AC41: 17593 | AD41: 35
L42: Suez | M42: 58.7 | N42: 19.6 | W42: Grand Total | X42: 516747 | Y42: 193323 | Z42: 1759.9 | AA42: 516.7 | AB42: 1133831 | AC42: 649760 | AD42: 965

Sheet Sheet1
AD1: governorate | AE1: Count of customer_id | AI1: operator | AJ1: Sum of monthly_revenue_EGP | AN1: device_tier | AO1: Sum of monthly_revenue_EGP | AT1: customer_segment | AU1: Average of satisfaction_score
AD2: أسوان | AE2: 60 | AI2: e& | AJ2: 140689.03 | AN2: Basic Smartphone | AO2: 13493.46 | AT2: Business | AU2: 3.6153846
AD3: أسيوط | AE3: 138 | AI3: Orange | AJ3: 273765.67 | AN3: Budget Smartphone | AO3: 247396.16 | AT3: Low | AU3: 3.6180666
AD4: الإسكندرية | AE4: 490 | AI4: Vodafone | AJ4: 427367.76 | AN4: Feature Phone | AO4: 88428.72 | AT4: Regular | AU4: 3.5960625
AD5: الإسماعيلية | AE5: 110 | AI5: WE | AJ5: 100453.27 | AN5: Mid Smartphone | AO5: 373784.81 | AT5: VIP | AU5: 3.6640927
AD6: الأقصر | AE6: 61 | AN6: Premium Smartphone | AO6: 200514.42
AD7: البحر الأحمر | AE7: 46 | AN7: Tablet | AO7: 18658.16
AD8: البحيرة | AE8: 246
AD9: الجيزة | AE9: 515
AD10: الدقهلية | AE10: 278
AD11: السويس | AE11: 99
AD12: الشرقية | AE12: 329
AD13: الغربية | AE13: 248
AD14: الفيوم | AE14: 110
AD15: القاهرة | AE15: 933
AD16: القليوبية | AE16: 283
AD17: المنوفية | AE17: 205
AD18: المنيا | AE18: 142
AD19: الوادي الجديد | AE19: 22
... AD29: Grand Total | AE29: 5000
U62: governorate | V62: Sum of Sum of satisfaction_score
U63: الإسكندرية | V63: 1898
U64: الجيزة | V64: 2148
U65: الدقهلية | V65: 1246
U66: الشرقية | V66: 1363
U67: القاهرة | V67: 3595
